{"errorMessage": "HTTPSConnectionPool(host='api.iroco2.example.com', port=443): Max retries exceeded with url: / (Caused by NewConnectionError('<urllib3.connection.HTTPSConnection object at 0x7f99944316d0>: Failed to establish a new connection: [Errno -2] Name or service not known'))", "errorType": "ConnectionError", "requestId": "f52f8f03-07bb-431d-8451-496f74e1f4d2", "stackTrace": ["  File \"/var/task/cur_scrapper.py\", line 59, in handler\n    cur_processor_service.parsing_cur_and_send_to_api(\n", "  File \"/var/task/cur_scrapper.py\", line 42, in parsing_cur_and_send_to_api\n    self.__send_message_parsed_to_api(message_parsed)\n", "  File \"/var/task/cur_scrapper.py\", line 46, in __send_message_parsed_to_api\n    correlation_id = self.iroco_service.create_scan()\n", "  File \"/opt/python/iroco_service.py\", line 40, in create_scan\n    response = requests.post(self.iroco_endpoint, headers=self.__build_header())\n", "  File \"/opt/python/requests/api.py\", line 115, in post\n    return request(\"post\", url, data=data, json=json, **kwargs)\n", "  File \"/opt/python/requests/api.py\", line 59, in request\n    return session.request(method=method, url=url, **kwargs)\n", "  File \"/opt/python/requests/sessions.py\", line 589, in request\n    resp = self.send(prep, **send_kwargs)\n", "  File \"/opt/python/requests/sessions.py\", line 703, in send\n    r = adapter.send(request, **kwargs)\n", "  File \"/opt/python/requests/adapters.py\", line 700, in send\n    raise ConnectionError(e, request=request)\n"]}
